Workbook

Sheet  발주서
A1: 발 주 서
A2: 수신 : | F2: (주)에코센스 | S2: (인) | AA2: 발신 : | AF2: 주식회사 블루온 | AT2: (인)
A3: 참고 : | F3: 기술영업본부 | AA3: 담당자 : | AF3: 김서해 주임
A5: =TODAY() -> 45965 | O5: 등록번호 | W5: 679-86-02827 | AZ5: 사업장: | BA5: =$K$21&"(보조금 동시진행)" -> (주)네패스 음성(보조금 동시진행)
A6: (주)에코센스 귀하 아래와 같이 발주합니다. | O6: 상호명(법인명) | W6: 주식회사 블루온 | AG6: 대표자 | AO6: 김경수 | AZ6: PH센서 | BA6: =IFERROR(__xludf.DUMMYFUNCTION("IFERROR( XLOOKUP( $BA$5, INDEX( IMPORTRANGE(""https://docs.google.com/spreadsheets/d/1aJ8iXnyM-JhRgpO9l17mkDq2_VFDRDluD053wxjOUCM/edit"", ""'2. 25년 관리DB'!A:BV""), , MATCH(""사업장명"", INDEX(IMPORTRANGE(""https://docs.google.com/spreads"&"heets/d/1aJ8iXnyM-JhRgpO9l17mkDq2_VFDRDluD053wxjOUCM/edit"", ""'2. 25년 관리DB'!A1:BV1""), 1, ), 0) ), INDEX( IMPORTRANGE(""https://docs.google.com/spreadsheets/d/1aJ8iXnyM-JhRgpO9l17mkDq2_VFDRDluD053wxjOUCM/edit"", ""'2. 25년 관리DB'!A:BV""), "&" , MATCH(AZ6, INDEX(IMPORTRANGE(""https://docs.google.com/spreadsheets/d/1aJ8iXnyM-JhRgpO9l17mkDq2_VFDRDluD053wxjOUCM/edit"", ""'2. 25년 관리DB'!A1:BV1""), 1, ), 0) ) ), """" ) "),"")
O7: 주소 | W7: 경상북도 고령군 대가야읍 낫질로 285 | AZ7: 차압계 | BA7: =IFERROR(__xludf.DUMMYFUNCTION("IFERROR( XLOOKUP( $BA$5, INDEX( IMPORTRANGE(""https://docs.google.com/spreadsheets/d/1aJ8iXnyM-JhRgpO9l17mkDq2_VFDRDluD053wxjOUCM/edit"", ""'2. 25년 관리DB'!A:BV""), , MATCH(""사업장명"", INDEX(IMPORTRANGE(""https://docs.google.com/spreads"&"heets/d/1aJ8iXnyM-JhRgpO9l17mkDq2_VFDRDluD053wxjOUCM/edit"", ""'2. 25년 관리DB'!A1:BV1""), 1, ), 0) ), INDEX( IMPORTRANGE(""https://docs.google.com/spreadsheets/d/1aJ8iXnyM-JhRgpO9l17mkDq2_VFDRDluD053wxjOUCM/edit"", ""'2. 25년 관리DB'!A:BV""), "&" , MATCH(AZ7, INDEX(IMPORTRANGE(""https://docs.google.com/spreadsheets/d/1aJ8iXnyM-JhRgpO9l17mkDq2_VFDRDluD053wxjOUCM/edit"", ""'2. 25년 관리DB'!A1:BV1""), 1, ), 0) ) ), """" ) "),"")
O8: 업태 | W8: 서비스업 | AG8: 종목 | AO8: 소프트웨어개발및판매 | AZ8: 온도계 | BA8: =IFERROR(__xludf.DUMMYFUNCTION("IFERROR( XLOOKUP( $BA$5, INDEX( IMPORTRANGE(""https://docs.google.com/spreadsheets/d/1aJ8iXnyM-JhRgpO9l17mkDq2_VFDRDluD053wxjOUCM/edit"", ""'2. 25년 관리DB'!A:BV""), , MATCH(""사업장명"", INDEX(IMPORTRANGE(""https://docs.google.com/spreads"&"heets/d/1aJ8iXnyM-JhRgpO9l17mkDq2_VFDRDluD053wxjOUCM/edit"", ""'2. 25년 관리DB'!A1:BV1""), 1, ), 0) ), INDEX( IMPORTRANGE(""https://docs.google.com/spreadsheets/d/1aJ8iXnyM-JhRgpO9l17mkDq2_VFDRDluD053wxjOUCM/edit"", ""'2. 25년 관리DB'!A:BV""), "&" , MATCH(AZ8, INDEX(IMPORTRANGE(""https://docs.google.com/spreadsheets/d/1aJ8iXnyM-JhRgpO9l17mkDq2_VFDRDluD053wxjOUCM/edit"", ""'2. 25년 관리DB'!A1:BV1""), 1, ), 0) ) ), """" ) "),"")
O9: 전화번호 | W9: 1661-5543 | AG9: 팩스 | AO9: 031-8077-2054 | AZ9: 배출CT | BA9: =IFERROR(__xludf.DUMMYFUNCTION("LET( url, ""https://docs.google.com/spreadsheets/d/1aJ8iXnyM-JhRgpO9l17mkDq2_VFDRDluD053wxjOUCM/edit"", 시트, ""'2. 25년 관리DB'!"", 본문, IMPORTRANGE(url, 시트 & ""A:BV""), 헤더, INDEX(본문, 1, ), 사업장열, MATCH(""사업장명"", 헤더, 0), 배출열, MATCH(""배출전류계"", 헤더, 0)"&", 기준값, $BA$5, 사업장범위, INDEX(본문, , 사업장열), 배출값, IFERROR(XLOOKUP(기준값, 사업장범위, INDEX(본문, , 배출열)), 0), 배출값 ) "),0) -> 0
A10: 방지시설 IoT | M10: 단위 | S10: 수량 | Y10: 단가(원) | AG10: 금액(원) | AO10: 비고 | AZ10: 방지CT | BA10: =IFERROR(__xludf.DUMMYFUNCTION("LET( url, ""https://docs.google.com/spreadsheets/d/1aJ8iXnyM-JhRgpO9l17mkDq2_VFDRDluD053wxjOUCM/edit"", 시트, ""'2. 25년 관리DB'!"", 본문, IMPORTRANGE(url, 시트 & ""A:BV""), 헤더, INDEX(본문, 1, ), 사업장열, MATCH(""사업장명"", 헤더, 0), 송풍열, MATCH(""송풍전류계"", 헤더, 0)"&", 펌프열, MATCH(""펌프전류계"", 헤더, 0), 기준값, $BA$5, 사업장범위, INDEX(본문, , 사업장열), 송풍값, IFERROR(XLOOKUP(기준값, 사업장범위, INDEX(본문, , 송풍열)), 0), 펌프값, IFERROR(XLOOKUP(기준값, 사업장범위, INDEX(본문, , 펌프열)), 0), 송풍값 + 펌프값 ) "),0) -> 0
AZ11: G/W(3,4CH) | BA11: =IFERROR(__xludf.DUMMYFUNCTION("IFERROR( XLOOKUP( $BA$5, INDEX( IMPORTRANGE(""https://docs.google.com/spreadsheets/d/1aJ8iXnyM-JhRgpO9l17mkDq2_VFDRDluD053wxjOUCM/edit"", ""'2. 25년 관리DB'!A:BV""), , MATCH(""사업장명"", INDEX(IMPORTRANGE(""https://docs.google.com/spreads"&"heets/d/1aJ8iXnyM-JhRgpO9l17mkDq2_VFDRDluD053wxjOUCM/edit"", ""'2. 25년 관리DB'!A1:BV1""), 1, ), 0) ), INDEX( IMPORTRANGE(""https://docs.google.com/spreadsheets/d/1aJ8iXnyM-JhRgpO9l17mkDq2_VFDRDluD053wxjOUCM/edit"", ""'2. 25년 관리DB'!A:BV""), "&" , MATCH(AZ11, INDEX(IMPORTRANGE(""https://docs.google.com/spreadsheets/d/1aJ8iXnyM-JhRgpO9l17mkDq2_VFDRDluD053wxjOUCM/edit"", ""'2. 25년 관리DB'!A1:BV1""), 1, ), 0) ) ), """" ) "),"")
A12: 구분 | H12: PH센서 | N12: 차압계 | T12: 온도계 | Z12: CT | AF12: 2CH GW | AL12: 계측보드 | AR12: VPN | AZ12: G/W(1,2CH) | BA12: =IFERROR(__xludf.DUMMYFUNCTION("IFERROR( XLOOKUP( $BA$5, INDEX( IMPORTRANGE(""https://docs.google.com/spreadsheets/d/1aJ8iXnyM-JhRgpO9l17mkDq2_VFDRDluD053wxjOUCM/edit"", ""'2. 25년 관리DB'!A:BV""), , MATCH(""사업장명"", INDEX(IMPORTRANGE(""https://docs.google.com/spreads"&"heets/d/1aJ8iXnyM-JhRgpO9l17mkDq2_VFDRDluD053wxjOUCM/edit"", ""'2. 25년 관리DB'!A1:BV1""), 1, ), 0) ), INDEX( IMPORTRANGE(""https://docs.google.com/spreadsheets/d/1aJ8iXnyM-JhRgpO9l17mkDq2_VFDRDluD053wxjOUCM/edit"", ""'2. 25년 관리DB'!A:BV""), "&" , MATCH(AZ12, INDEX(IMPORTRANGE(""https://docs.google.com/spreadsheets/d/1aJ8iXnyM-JhRgpO9l17mkDq2_VFDRDluD053wxjOUCM/edit"", ""'2. 25년 관리DB'!A1:BV1""), 1, ), 0) ) ), """" ) "),"")
A13: 총수량 | H13: 1 | N13: 1 | T13: 1 | Z13: 14 | AF13: 0 | AL13: 1 | AR13: 0 | AZ13: VPN | BA13: =IFERROR(__xludf.DUMMYFUNCTION("IFERROR( XLOOKUP( $K$21, INDEX( IMPORTRANGE(""https://docs.google.com/spreadsheets/d/1aJ8iXnyM-JhRgpO9l17mkDq2_VFDRDluD053wxjOUCM/edit"", ""'2. 25년 관리DB'!A:BV""), , MATCH(""사업장명"", INDEX(IMPORTRANGE(""https://docs.google.com/spreads"&"heets/d/1aJ8iXnyM-JhRgpO9l17mkDq2_VFDRDluD053wxjOUCM/edit"", ""'2. 25년 관리DB'!A1:BV1""), 1, ), 0) ), INDEX( IMPORTRANGE(""https://docs.google.com/spreadsheets/d/1aJ8iXnyM-JhRgpO9l17mkDq2_VFDRDluD053wxjOUCM/edit"", ""'2. 25년 관리DB'!A:BV""), "&" , MATCH(AZ13, INDEX(IMPORTRANGE(""https://docs.google.com/spreadsheets/d/1aJ8iXnyM-JhRgpO9l17mkDq2_VFDRDluD053wxjOUCM/edit"", ""'2. 25년 관리DB'!A1:BV1""), 1, ), 0) ) ), """" ) "),"2. 유선") -> 2. 유선
A14: 총 계 | N14: =단가!B34 -> 2070000 | AL14: 원(부가세별도)
A16: 필수 기입 / 체크(O) 사항
A18: no | D18: 항목 | K18: 기입내용
A19: 1 | D19: 설치(납품)희망일자 | U19: =A5+7 -> 45972
A20: 2 | D20: 설치공장정보 | K20: 공장명 | U20: 담당자명 | AE20: 연락처 | AO20: 이메일
K21: (주)네패스 음성 | U21: =IFERROR(__xludf.DUMMYFUNCTION("IFERROR( XLOOKUP( $K$21, INDEX( IMPORTRANGE(""https://docs.google.com/spreadsheets/d/1aJ8iXnyM-JhRgpO9l17mkDq2_VFDRDluD053wxjOUCM/edit"", ""'2. 25년 관리DB'!A:BV""), , MATCH(""사업장명"", INDEX(IMPORTRANGE(""https://docs.google.com/spreads"&"heets/d/1aJ8iXnyM-JhRgpO9l17mkDq2_VFDRDluD053wxjOUCM/edit"", ""'2. 25년 관리DB'!A1:BV1""), 1, ), 0) ), INDEX( IMPORTRANGE(""https://docs.google.com/spreadsheets/d/1aJ8iXnyM-JhRgpO9l17mkDq2_VFDRDluD053wxjOUCM/edit"", ""'2. 25년 관리DB'!A:BV""), "&" , MATCH(""사업장담당자"", INDEX(IMPORTRANGE(""https://docs.google.com/spreadsheets/d/1aJ8iXnyM-JhRgpO9l17mkDq2_VFDRDluD053wxjOUCM/edit"", ""'2. 25년 관리DB'!A1:BV1""), 1, ), 0) ) ), """" ) "),"최지은") -> 최지은 | AE21: =IFERROR(__xludf.DUMMYFUNCTION("IFERROR( XLOOKUP( $K$21, INDEX( IMPORTRANGE(""https://docs.google.com/spreadsheets/d/1aJ8iXnyM-JhRgpO9l17mkDq2_VFDRDluD053wxjOUCM/edit"", ""'2. 25년 관리DB'!A:BV""), , MATCH(""사업장명"", INDEX(IMPORTRANGE(""https://docs.google.com/spreads"&"heets/d/1aJ8iXnyM-JhRgpO9l17mkDq2_VFDRDluD053wxjOUCM/edit"", ""'2. 25년 관리DB'!A1:BV1""), 1, ), 0) ), INDEX( IMPORTRANGE(""https://docs.google.com/spreadsheets/d/1aJ8iXnyM-JhRgpO9l17mkDq2_VFDRDluD053wxjOUCM/edit"", ""'2. 25년 관리DB'!A:BV""), "&" , MATCH(""연락처"", INDEX(IMPORTRANGE(""https://docs.google.com/spreadsheets/d/1aJ8iXnyM-JhRgpO9l17mkDq2_VFDRDluD053wxjOUCM/edit"", ""'2. 25년 관리DB'!A1:BV1""), 1, ), 0) ) ), """" ) "),"010-3279-0092") -> 010-3279-0092 | AO21: =IFERROR(__xludf.DUMMYFUNCTION("IFERROR( XLOOKUP( $K$21, INDEX( IMPORTRANGE(""https://docs.google.com/spreadsheets/d/1aJ8iXnyM-JhRgpO9l17mkDq2_VFDRDluD053wxjOUCM/edit"", ""'2. 25년 관리DB'!A:BV""), , MATCH(""사업장명"", INDEX(IMPORTRANGE(""https://docs.google.com/spreads"&"heets/d/1aJ8iXnyM-JhRgpO9l17mkDq2_VFDRDluD053wxjOUCM/edit"", ""'2. 25년 관리DB'!A1:BV1""), 1, ), 0) ), INDEX( IMPORTRANGE(""https://docs.google.com/spreadsheets/d/1aJ8iXnyM-JhRgpO9l17mkDq2_VFDRDluD053wxjOUCM/edit"", ""'2. 25년 관리DB'!A:BV""), "&" , MATCH(""이메일"", INDEX(IMPORTRANGE(""https://docs.google.com/spreadsheets/d/1aJ8iXnyM-JhRgpO9l17mkDq2_VFDRDluD053wxjOUCM/edit"", ""'2. 25년 관리DB'!A1:BV1""), 1, ), 0) ) ), """" ) "),"choije0310@nepes.co.kr") -> choije0310@nepes.co.kr
K22: 설치공장주소 | U22: =IFERROR(__xludf.DUMMYFUNCTION("IFERROR( XLOOKUP( $K$21, INDEX( IMPORTRANGE(""https://docs.google.com/spreadsheets/d/1aJ8iXnyM-JhRgpO9l17mkDq2_VFDRDluD053wxjOUCM/edit"", ""'2. 25년 관리DB'!A:BV""), , MATCH(""사업장명"", INDEX(IMPORTRANGE(""https://docs.google.com/spreads"&"heets/d/1aJ8iXnyM-JhRgpO9l17mkDq2_VFDRDluD053wxjOUCM/edit"", ""'2. 25년 관리DB'!A1:BV1""), 1, ), 0) ), INDEX( IMPORTRANGE(""https://docs.google.com/spreadsheets/d/1aJ8iXnyM-JhRgpO9l17mkDq2_VFDRDluD053wxjOUCM/edit"", ""'2. 25년 관리DB'!A:BV""), "&" , MATCH(""주소"", INDEX(IMPORTRANGE(""https://docs.google.com/spreadsheets/d/1aJ8iXnyM-JhRgpO9l17mkDq2_VFDRDluD053wxjOUCM/edit"", ""'2. 25년 관리DB'!A1:BV1""), 1, ), 0) ) ), """" ) "),"충청북도 음성군 금일로 965번길 105") -> 충청북도 음성군 금일로 965번길 105
K23: 택배주소 | U23: 화성지점 : 경기도 화성시 팔탈면 푸른들판로 461-53, IoT관리부 김서해(010-4320-3521)
A24: 3 | D24: 그린링크정보 (코드번호) | K24: 사업장코드(숫자) | U24: 송풍시설코드(F) | AE24: 방지시설코드(P) | AO24: 배출시설코드(E)
K25: =IFERROR(__xludf.DUMMYFUNCTION("IFERROR( XLOOKUP( $K$21, INDEX( IMPORTRANGE(""https://docs.google.com/spreadsheets/d/1aJ8iXnyM-JhRgpO9l17mkDq2_VFDRDluD053wxjOUCM/edit"", ""'2. 25년 관리DB'!A:BV""), , MATCH(""사업장명"", INDEX(IMPORTRANGE(""https://docs.google.com/spreads"&"heets/d/1aJ8iXnyM-JhRgpO9l17mkDq2_VFDRDluD053wxjOUCM/edit"", ""'2. 25년 관리DB'!A1:BV1""), 1, ), 0) ), INDEX( IMPORTRANGE(""https://docs.google.com/spreadsheets/d/1aJ8iXnyM-JhRgpO9l17mkDq2_VFDRDluD053wxjOUCM/edit"", ""'2. 25년 관리DB'!A:BV""), "&" , MATCH(""사업장관리코드"", INDEX(IMPORTRANGE(""https://docs.google.com/spreadsheets/d/1aJ8iXnyM-JhRgpO9l17mkDq2_VFDRDluD053wxjOUCM/edit"", ""'2. 25년 관리DB'!A1:BV1""), 1, ), 0) ) ), """" ) "),"-") -> - | U25: 1 | AE25: 501 | AO25: 1
K26: =IFERROR(__xludf.DUMMYFUNCTION("IFERROR( XLOOKUP( $K$21, INDEX( IMPORTRANGE(""https://docs.google.com/spreadsheets/d/1aJ8iXnyM-JhRgpO9l17mkDq2_VFDRDluD053wxjOUCM/edit"", ""'2. 25년 관리DB'!A:BV""), , MATCH(""사업장명"", INDEX(IMPORTRANGE(""https://docs.google.com/spreads"&"heets/d/1aJ8iXnyM-JhRgpO9l17mkDq2_VFDRDluD053wxjOUCM/edit"", ""'2. 25년 관리DB'!A1:BV1""), 1, ), 0) ), INDEX( IMPORTRANGE(""https://docs.google.com/spreadsheets/d/1aJ8iXnyM-JhRgpO9l17mkDq2_VFDRDluD053wxjOUCM/edit"", ""'2. 25년 관리DB'!A:BV""), "&" , MATCH(""사업장관리코드"", INDEX(IMPORTRANGE(""https://docs.google.com/spreadsheets/d/1aJ8iXnyM-JhRgpO9l17mkDq2_VFDRDluD053wxjOUCM/edit"", ""'2. 25년 관리DB'!A1:BV1""), 1, ), 0) ) ), """" ) "),"-") -> -
K27: =IFERROR(__xludf.DUMMYFUNCTION("IFERROR( XLOOKUP( $K$21, INDEX( IMPORTRANGE(""https://docs.google.com/spreadsheets/d/1aJ8iXnyM-JhRgpO9l17mkDq2_VFDRDluD053wxjOUCM/edit"", ""'2. 25년 관리DB'!A:BV""), , MATCH(""사업장명"", INDEX(IMPORTRANGE(""https://docs.google.com/spreads"&"heets/d/1aJ8iXnyM-JhRgpO9l17mkDq2_VFDRDluD053wxjOUCM/edit"", ""'2. 25년 관리DB'!A1:BV1""), 1, ), 0) ), INDEX( IMPORTRANGE(""https://docs.google.com/spreadsheets/d/1aJ8iXnyM-JhRgpO9l17mkDq2_VFDRDluD053wxjOUCM/edit"", ""'2. 25년 관리DB'!A:BV""), "&" , MATCH(""사업장관리코드"", INDEX(IMPORTRANGE(""https://docs.google.com/spreadsheets/d/1aJ8iXnyM-JhRgpO9l17mkDq2_VFDRDluD053wxjOUCM/edit"", ""'2. 25년 관리DB'!A1:BV1""), 1, ), 0) ) ), """" ) "),"-") -> -
K28: =IFERROR(__xludf.DUMMYFUNCTION("IFERROR( XLOOKUP( $K$21, INDEX( IMPORTRANGE(""https://docs.google.com/spreadsheets/d/1aJ8iXnyM-JhRgpO9l17mkDq2_VFDRDluD053wxjOUCM/edit"", ""'2. 25년 관리DB'!A:BV""), , MATCH(""사업장명"", INDEX(IMPORTRANGE(""https://docs.google.com/spreads"&"heets/d/1aJ8iXnyM-JhRgpO9l17mkDq2_VFDRDluD053wxjOUCM/edit"", ""'2. 25년 관리DB'!A1:BV1""), 1, ), 0) ), INDEX( IMPORTRANGE(""https://docs.google.com/spreadsheets/d/1aJ8iXnyM-JhRgpO9l17mkDq2_VFDRDluD053wxjOUCM/edit"", ""'2. 25년 관리DB'!A:BV""), "&" , MATCH(""사업장관리코드"", INDEX(IMPORTRANGE(""https://docs.google.com/spreadsheets/d/1aJ8iXnyM-JhRgpO9l17mkDq2_VFDRDluD053wxjOUCM/edit"", ""'2. 25년 관리DB'!A1:BV1""), 1, ), 0) ) ), """" ) "),"-") -> -
K29: =IFERROR(__xludf.DUMMYFUNCTION("IFERROR( XLOOKUP( $K$21, INDEX( IMPORTRANGE(""https://docs.google.com/spreadsheets/d/1aJ8iXnyM-JhRgpO9l17mkDq2_VFDRDluD053wxjOUCM/edit"", ""'2. 25년 관리DB'!A:BV""), , MATCH(""사업장명"", INDEX(IMPORTRANGE(""https://docs.google.com/spreads"&"heets/d/1aJ8iXnyM-JhRgpO9l17mkDq2_VFDRDluD053wxjOUCM/edit"", ""'2. 25년 관리DB'!A1:BV1""), 1, ), 0) ), INDEX( IMPORTRANGE(""https://docs.google.com/spreadsheets/d/1aJ8iXnyM-JhRgpO9l17mkDq2_VFDRDluD053wxjOUCM/edit"", ""'2. 25년 관리DB'!A:BV""), "&" , MATCH(""사업장관리코드"", INDEX(IMPORTRANGE(""https://docs.google.com/spreadsheets/d/1aJ8iXnyM-JhRgpO9l17mkDq2_VFDRDluD053wxjOUCM/edit"", ""'2. 25년 관리DB'!A1:BV1""), 1, ), 0) ) ), """" ) "),"-") -> -
K30: =IFERROR(__xludf.DUMMYFUNCTION("IFERROR( XLOOKUP( $K$21, INDEX( IMPORTRANGE(""https://docs.google.com/spreadsheets/d/1aJ8iXnyM-JhRgpO9l17mkDq2_VFDRDluD053wxjOUCM/edit"", ""'2. 25년 관리DB'!A:BV""), , MATCH(""사업장명"", INDEX(IMPORTRANGE(""https://docs.google.com/spreads"&"heets/d/1aJ8iXnyM-JhRgpO9l17mkDq2_VFDRDluD053wxjOUCM/edit"", ""'2. 25년 관리DB'!A1:BV1""), 1, ), 0) ), INDEX( IMPORTRANGE(""https://docs.google.com/spreadsheets/d/1aJ8iXnyM-JhRgpO9l17mkDq2_VFDRDluD053wxjOUCM/edit"", ""'2. 25년 관리DB'!A:BV""), "&" , MATCH(""사업장관리코드"", INDEX(IMPORTRANGE(""https://docs.google.com/spreadsheets/d/1aJ8iXnyM-JhRgpO9l17mkDq2_VFDRDluD053wxjOUCM/edit"", ""'2. 25년 관리DB'!A1:BV1""), 1, ), 0) ) ), """" ) "),"-") -> -
K31: =IFERROR(__xludf.DUMMYFUNCTION("IFERROR( XLOOKUP( $K$21, INDEX( IMPORTRANGE(""https://docs.google.com/spreadsheets/d/1aJ8iXnyM-JhRgpO9l17mkDq2_VFDRDluD053wxjOUCM/edit"", ""'2. 25년 관리DB'!A:BV""), , MATCH(""사업장명"", INDEX(IMPORTRANGE(""https://docs.google.com/spreads"&"heets/d/1aJ8iXnyM-JhRgpO9l17mkDq2_VFDRDluD053wxjOUCM/edit"", ""'2. 25년 관리DB'!A1:BV1""), 1, ), 0) ), INDEX( IMPORTRANGE(""https://docs.google.com/spreadsheets/d/1aJ8iXnyM-JhRgpO9l17mkDq2_VFDRDluD053wxjOUCM/edit"", ""'2. 25년 관리DB'!A:BV""), "&" , MATCH(""사업장관리코드"", INDEX(IMPORTRANGE(""https://docs.google.com/spreadsheets/d/1aJ8iXnyM-JhRgpO9l17mkDq2_VFDRDluD053wxjOUCM/edit"", ""'2. 25년 관리DB'!A1:BV1""), 1, ), 0) ) ), """" ) "),"-") -> -
K32: 그린링크 사이트 : www.greenlink.or.kr (발주 전 가입 진행 부탁드립니다.)
A33: 4 | D33: 설치정보 | K33: 구분 | U33: 자체(고객)설치 | AJ33: 에코센스설치
K34: IoT 장치부착 | AJ34: V
K35: 케이블포설 | AJ35: V
K36: 통신방식 (VPN社:시큐위즈) | U36: 보안인증 NO. NISS-1019 / Secuway SSL U V2.0
U37: 유선(랜선공사, 선 포설거리 60M 이내) | AJ37: 무선 (매월 15,400원, VAT 포함)
AJ38: =IF($BA$13="2. 유선","V","") -> V
A39: 5 | D39: CT(전류측정계) 사양(도선굵기) | K39: 구분 | U39: 16L | AE39: 24L | AO39: 36L
K40: 메인차단기 허용전류 | U40: ~200A미만 | AE40: 200A이상 ~ 300A미만 | AO40: 300A이상 ~ 600A미만
K41: 방지시설 | U41: =IFERROR(__xludf.DUMMYFUNCTION("LET( url, ""https://docs.google.com/spreadsheets/d/1aJ8iXnyM-JhRgpO9l17mkDq2_VFDRDluD053wxjOUCM/edit"", 시트, ""'2. 25년 관리DB'!"", 본문, IMPORTRANGE(url, 시트 & ""A:BV""), 헤더, INDEX(본문, 1, ), 사업장열, MATCH(""사업장명"", 헤더, 0), 송풍열, MATCH(""송풍전류계"", 헤더, 0)"&", 펌프열, MATCH(""펌프전류계"", 헤더, 0), 기준값2, $BA$5, 기준값1, $K$21, 사업장범위, INDEX(본문, , 사업장열), 송풍값1, IFERROR(XLOOKUP(기준값1, 사업장범위, INDEX(본문, , 송풍열)), 0), 펌프값1, IFERROR(XLOOKUP(기준값1, 사업장범위, INDEX(본문, , 펌프열)), 0), 송풍값2, IFERROR(XLOOKUP(기준값2, 사업장범위, INDEX"&"(본문, , 송풍열)), 0), 펌프값2, IFERROR(XLOOKUP(기준값2, 사업장범위, INDEX(본문, , 펌프열)), 0), 송풍값1 + 펌프값1 + 송풍값2 + 펌프값2 ) "),0) -> 0
K42: 배출시설 | U42: =IFERROR(__xludf.DUMMYFUNCTION("LET( url, ""https://docs.google.com/spreadsheets/d/1aJ8iXnyM-JhRgpO9l17mkDq2_VFDRDluD053wxjOUCM/edit"", 시트, ""'2. 25년 관리DB'!"", 본문, IMPORTRANGE(url, 시트 & ""A:BV""), 헤더, INDEX(본문, 1, ), 사업장열, MATCH(""사업장명"", 헤더, 0), 배출열, MATCH(""배출전류계"", 헤더, 0)"&", 기준값2, $BA$5, 기준값1, $K$21, 사업장범위, INDEX(본문, , 사업장열), 배출값1, IFERROR(XLOOKUP(기준값1, 사업장범위, INDEX(본문, , 배출열)), 0), 배출값2, IFERROR(XLOOKUP(기준값2, 사업장범위, INDEX(본문, , 배출열)), 0), 배출값1 + 배출값2 ) "),0) -> 0
A43: 6 | D43: 온도센서타입 | U43: 프렌지타입 | AJ43: 니플(소켓)타입
...

Sheet 단가
A1: 연번 | B1: 품목 | C1: 총판가('25.03) | D1: 24년도 단가
A2: =ROW()-1 -> 1 | B2: PH계보상 | C2: 580000 | D2: 620000
A3: =ROW()-1 -> 2 | B3: PH센서 | C3: 580000 | D3: 620000
A4: =ROW()-1 -> 3 | B4: 차압계 | C4: 140000 | D4: 190000
A5: =ROW()-1 -> 4 | B5: 온도계 | C5: 120000 | D5: 140000
A6: =ROW()-1 -> 5 | B6: 차압계(방폭) | D6: 1000000
A7: =ROW()-1 -> 6 | B7: 온도계(방폭) | D7: 300000
A8: =ROW()-1 -> 7 | B8: 확장디바이스 | C8: 520000 | D8: 620000
A9: =ROW()-1 -> 8 | B9: CT | C9: 70000 | D9: 70000
A10: =ROW()-1 -> 9 | B10: CTM | D10: 0
A11: =ROW()-1 -> 10 | B11: SD카드 | D11: 0
A12: 11 | B12: 계측보드 | C12: 250000
A13: =ROW()-1 -> 12 | B13: 1CH GW | C13: 1000000 | D13: 1380000
A14: =ROW()-1 -> 13 | B14: 1CH GW(VPN유선) | C14: =C13+100000 -> 1100000
A15: =ROW()-1 -> 14 | B15: 1CH GW(VPN무선) | C15: =C13 -> 1000000 | D15: 1380000
A16: =ROW()-1 -> 15 | B16: SUS재질_1CH GW(VPN유선) | C16: 1700000
A17: =ROW()-1 -> 16 | B17: SUS재질_1CH GW(VPN무선) | C17: 1600000
A18: =ROW()-1 -> 17 | B18: 2CH GW | C18: 1000000 | D18: 1380000
A19: =ROW()-1 -> 18 | B19: 2CH GW(VPN유선) | C19: =C18+100000 -> 1100000
A20: =ROW()-1 -> 19 | B20: 2CH GW(VPN무선) | C20: =C18 -> 1000000 | D20: 1380000
A21: =ROW()-1 -> 20 | B21: SUS재질_2CH GW(VPN유선) | C21: 1700000
A22: =ROW()-1 -> 21 | B22: SUS재질_2CH GW(VPN무선) | C22: 1600000
A23: =ROW()-1 -> 22 | B23: 3CH GW | C23: 1420000 | D23: 1660000
A24: =ROW()-1 -> 23 | B24: 3CH GW(VPN유선) | C24: =C23+100000 -> 1520000
A25: =ROW()-1 -> 24 | B25: 3CH GW(VPN무선) | C25: =C23 -> 1420000 | D25: 1660000
A26: =ROW()-1 -> 25 | B26: SUS재질_3CH GW(VPN유선) | C26: 2320000
A27: =ROW()-1 -> 26 | B27: SUS재질_3CH GW(VPN무선) | C27: 2220000
A28: =ROW()-1 -> 27 | B28: 4CH GW | C28: 1420000 | D28: 1660000
A29: =ROW()-1 -> 28 | B29: 4CH GW(VPN유선) | C29: =C28+100000 -> 1520000
A30: =ROW()-1 -> 29 | B30: 4CH GW(VPN무선) | C30: =C28 -> 1420000 | D30: 1660000
A31: =ROW()-1 -> 30 | B31: SUS재질_4CH GW(VPN유선) | C31: 2320000
A32: =ROW()-1 -> 31 | B32: SUS재질_4CH GW(VPN무선) | C32: 2220000
A33: 소계 | B33: =IFERROR(VLOOKUP(' 발주서'!H$12,단가!$B$2:$D$32,2,0)*' 발주서'!H$13,"") -> 580000 | C33: =IFERROR(VLOOKUP(' 발주서'!T$12,단가!$B$2:$D$32,2,0)*' 발주서'!T$13,"") -> 120000 | D33: =IFERROR(VLOOKUP(' 발주서'!N$12,단가!$B$2:$D$32,2,0)*' 발주서'!N$13,"") -> 140000 | E33: =IFERROR(VLOOKUP(' 발주서'!Z$12,단가!$B$2:$D$32,2,0)*' 발주서'!Z$13,"") -> 980000 | F33: =IFERROR(VLOOKUP(' 발주서'!AF$12,단가!$B$2:$D$32,2,0)*' 발주서'!AF$13,"") -> 0 | G33: =IFERROR(VLOOKUP(' 발주서'!AL$12,단가!$B$2:$D$32,2,0)*' 발주서'!AL$13,"") -> 250000
A34: 합계 | B34: =SUM(B33:G33) -> 2070000

Sheet 담당
A1: 연번 | B1: 이름 | C1: 연락처 | D1: E-MAIL
A2: =ROW()-1 -> 1 | B2: 황근석 부장 | C2: 010-5158-0766 | D2: marinserver07@gmail.com
A3: =ROW()-1 -> 2 | B3: 최문호 차장 | C3: 010-6359-0521 | D3: mhc853@gmail.com
A4: =ROW()-1 -> 3 | B4: 박성민 과장 | C4: 010-4031-4858 | D4: psm19911@naver.com
A5: =ROW()-1 -> 4 | B5: 손병준 과장 | C5: 010-4475-3130 | D5: revir66@naver.com
A6: =ROW()-1 -> 5 | B6: 박지영 과장 | C6: 010-5694-6964 | D6: hana01056946964@gmail.com
A7: =ROW()-1 -> 6 | B7: 이순희 과장 | C7: 010-7267-3651 | D7: yjtech5543@naver.com
A8: =ROW()-1 -> 7 | B8: 최재윤 주임 | C8: 010-7519-6964 | D8: nobrand48@naver.com
A9: =ROW()-1 -> 8 | B9: 김서해 주임 | C9: 010-4320-3521 | D9: seoh1523@gmail.com
A10: =ROW()-1 -> 9
A11: =ROW()-1 -> 10
A12: =ROW()-1 -> 11
A13: =ROW()-1 -> 12
A14: =ROW()-1 -> 13
A15: =ROW()-1 -> 14
A16: =ROW()-1 -> 15
A17: =ROW()-1 -> 16
A18: =ROW()-1 -> 17
A19: =ROW()-1 -> 18
A20: =ROW()-1 -> 19
A21: =ROW()-1 -> 20

Sheet 배송지
A1: 연번 | B1: 담당자 | C1: 연락처 | D1: 배송지
A2: 1 | B2: 오희경 | C2: 010-8224-0478 | D2: 유천포스코더샾 대구광역시 달서구 달서대로 67, 103동 2101호 오희경 실장(010-8224-0478)
A3: 2 | B3: 강영준 | C3: 010-3819-6875 | D3: 도깨비밥통 주소 : 대구 남구 봉덕로 21길48. 도깨비밥통강영준 010-3819-6875
A4: 3 | B4: 옥유준 | C4: 010-3691-6208 | D4: 부산광역시 사하구다대로470 다대해송아파트 101동704호 옥유준 (010-3691-6208)
A5: 4 | B5: 옥유준(경동택배) | C5: 010-3691-6208 | D5: 경동택배 부산사하장림 1090 영업소 부산광역시 사하구 다산로226번길 32 옥유준 (010-3691-6208)
A6: 5 | B6: 박성민 | C6: 010-4031-4858 | D6: 수원지점 : 경기도 수원시 매영로 252, 2층 IoT 영업부 박성민(010-4031-4858)
A7: 6 | B7: 최문호 | C7: 010-4953-1019 | D7: 화성지점 : 경기도 화성시 팔탈면 푸른들판로 461-53, IoT관리부 최문호(010-6359-0521)
A8: 7 | B8: 편진근 | C8: 010-7506-9450 | D8: 화성지점 : 경기도 화성시 팔탈면 푸른들판로 461-53, IoT관리부 편진근(010-7506-9450)
A9: 8 | B9: 김서해 | C9: 010-4320-3521 | D9: 화성지점 : 경기도 화성시 팔탈면 푸른들판로 461-53, IoT관리부 김서해(010-4320-3521)
A10: 9
A11: 10
